Workbook

Sheet Cover
B2: DEALDESK CRE UNDERWRITING
B3: Investment Underwriting Model
B5: =Assumptions!C5
B6: =Assumptions!C6
B8: Property Type: | C8: =Assumptions!C7
B9: Project Type: | C9: =Assumptions!C8
B10: Units: | C10: =Assumptions!C9
B11: Building SF: | C11: =Assumptions!C10
B13: KEY METRICS
B14: Purchase Price | C14: =Assumptions!C17
B15: Price Per Unit | C15: =Assumptions!C22
B16: Total Project Cost | C16: =Assumptions!C89
B17: Total Equity | C17: =Assumptions!C91
B18: Year 1 NOI | C18: ='Returns Summary'!B12
B19: Going-In Cap Rate | C19: ='Returns Summary'!B13
B20: Year 1 Cash-on-Cash | C20: ='Returns Summary'!B14
B21: Year 1 DSCR | C21: ='Returns Summary'!B15
B22: Equity Multiple | C22: ='Returns Summary'!B25
B23: Hold Period | C23: =Assumptions!C14
B24: LP IRR | C24: ='Cash Waterfall'!D41
B25: Levered IRR | C25: ='Cash Waterfall'!D30
B26: CONFIDENTIAL
B27: Prepared by DealDesk CRE Underwriting.

Sheet Assumptions
A1: DEALDESK — UNDERWRITING ASSUMPTIONS
A2: All blue values are editable inputs. Change any blue cell to model different scenarios.
B4: 1. PROPERTY INFORMATION
B5: Property Name | C5: Sample Property
B6: Address | C6: 123 Main St, Philadelphia, PA 19103
B7: Property Type | C7: Multifamily
B8: Project Type | C8: Sale
B9: Number of Units | C9: 20
B10: Gross Building Area (SF) | C10: 18000
B11: Lot Size (SF) | C11: 8500
B12: Year Built | C12: 1965
B13: Acquisition Date | C13: 2026-01-01
B14: Hold Period (Years) | C14: 10
B16: 2. ACQUISITION
B17: Purchase Price | C17: 2500000
B18: Transfer Tax Rate — Buyer's Share Only | C18: 0.02139
B19: Transfer Tax Amount | C19: =C17*C18
B20: Closing Costs | C20: 75000
B21: Total Acquisition Cost | C21: =C17+C19+C20
B22: Price Per Unit | C22: =IF(C9>0,C17/C9,0)
B23: Price Per SF | C23: =IF(C10>0,C17/C10,0)
B25: 3. SOURCES & USES
B26: Enter $0 for items not applicable.
B28: USES — Acquisition
B29: Purchase Price | C29: =C17
B30: Transfer Tax | C30: =C19
B31: Tenant Buyout | C31: 0
B33: USES — Professional & Due Diligence
B34: Legal — Closing & Borrowing | C34: 25000
B35: Title Insurance | C35: 8000
B36: Legal — Bank | C36: 5000
B37: Appraisal | C37: 5000
B38: Environmental (Phase I/II) | C38: 6000
B39: Architect | C39: 0
B40: Structural Engineer | C40: 0
B41: GeoTech | C41: 0
B42: Surveyor | C42: 3500
B43: Civil Engineer | C43: 0
B44: MEPs | C44: 0
B45: Legal — Zoning | C45: 0
...

Sheet Sources & Uses
A1: SOURCES & USES
A2: All values reference Assumptions tab. No hardcoded numbers.
A4: Line Item | B4: Amount | C4: % of Total
A5: Acquisition Costs
A6: Purchase Price | B6: =Assumptions!C17 | C6: =IF(B51<>0,B6/B51,0)
A7: Transfer Tax | B7: =Assumptions!C19 | C7: =IF(B51<>0,B7/B51,0)
A8: Tenant Buyout | B8: =Assumptions!C31 | C8: =IF(B51<>0,B8/B51,0)
A9: Subtotal — Acquisition Costs | B9: =SUM(B6:B8) | C9: =IF(B51<>0,B9/B51,0)
A11: Professional & Due Diligence
A12: Legal — Closing & Borrowing | B12: =Assumptions!C34 | C12: =IF(B51<>0,B12/B51,0)
A13: Title Insurance | B13: =Assumptions!C35 | C13: =IF(B51<>0,B13/B51,0)
A14: Legal — Bank | B14: =Assumptions!C36 | C14: =IF(B51<>0,B14/B51,0)
A15: Appraisal | B15: =Assumptions!C37 | C15: =IF(B51<>0,B15/B51,0)
A16: Environmental (Phase I/II) | B16: =Assumptions!C38 | C16: =IF(B51<>0,B16/B51,0)
A17: Architect | B17: =Assumptions!C39 | C17: =IF(B51<>0,B17/B51,0)
A18: Structural Engineer | B18: =Assumptions!C40 | C18: =IF(B51<>0,B18/B51,0)
A19: GeoTech | B19: =Assumptions!C41 | C19: =IF(B51<>0,B19/B51,0)
A20: Surveyor | B20: =Assumptions!C42 | C20: =IF(B51<>0,B20/B51,0)
A21: Civil Engineer | B21: =Assumptions!C43 | C21: =IF(B51<>0,B21/B51,0)
A22: MEPs | B22: =Assumptions!C44 | C22: =IF(B51<>0,B22/B51,0)
A23: Legal — Zoning | B23: =Assumptions!C45 | C23: =IF(B51<>0,B23/B51,0)
A24: Subtotal — Professional & Due Diligence | B24: =SUM(B12:B23) | C24: =IF(B51<>0,B24/B51,0)
A26: Financing Costs
A27: Acquisition Fee | B27: =Assumptions!C48 | C27: =IF(B51<>0,B27/B51,0)
A28: Mortgage Interest (Carry) | B28: =Assumptions!C49 | C28: =IF(B51<>0,B28/B51,0)
A29: Mortgage Fees / Origination | B29: =Assumptions!C50 | C29: =IF(B51<>0,B29/B51,0)
A30: Mezzanine Interest | B30: =Assumptions!C51 | C30: =IF(B51<>0,B30/B51,0)
A31: Subtotal — Financing Costs | B31: =SUM(B27:B30) | C31: =IF(B51<>0,B31/B51,0)
A33: Soft Costs
A34: Working Capital | B34: =Assumptions!C54 | C34: =IF(B51<>0,B34/B51,0)
A35: Marketing | B35: =Assumptions!C55 | C35: =IF(B51<>0,B35/B51,0)
A36: RE Tax (Carry) | B36: =Assumptions!C56 | C36: =IF(B51<>0,B36/B51,0)
A37: Prop / BR / Contr Insurance | B37: =Assumptions!C57 | C37: =IF(B51<>0,B37/B51,0)
A38: Development Fee | B38: =Assumptions!C58 | C38: =IF(B51<>0,B38/B51,0)
A39: Dev Equity Pref Return | B39: =Assumptions!C59 | C39: =IF(B51<>0,B39/B51,0)
A40: Permits / Expediting | B40: =Assumptions!C60 | C40: =IF(B51<>0,B40/B51,0)
A41: Subtotal — Soft Costs | B41: =SUM(B34:B40) | C41: =IF(B51<>0,B41/B51,0)
A43: Hard Costs
A44: Stormwater Mgmt | B44: =Assumptions!C63 | C44: =IF(B51<>0,B44/B51,0)
A45: Demolition & Site Work | B45: =Assumptions!C64 | C45: =IF(B51<>0,B45/B51,0)
...

Sheet Constr Interest

Sheet Sale Analysis
A1: SALE ANALYSIS
A2: Total project cost vs. net sale proceeds. Covers flips, build-to-sell, and land sales.
A4: TOTAL PROJECT COST
B5: Purchase Price | C5: =Assumptions!$C$17
B6: Transfer Tax & Closing | C6: =Assumptions!$C$19+Assumptions!$C$20
B7: Professional & DD Costs | C7: =SUM(Assumptions!$C$34:$C$45)
B8: Financing Costs | C8: =SUM(Assumptions!$C$48:$C$51)
B9: Soft Costs | C9: =SUM(Assumptions!$C$54:$C$60)
B10: Hard Costs (Construction/Reno) | C10: =SUM(Assumptions!$C$63:$C$67)
B12: TOTAL PROJECT COST | C12: =SUM(C5:C10)
A14: CARRY COSTS & TIMELINE
B15: Construction/Reno Period (Months) | C15: 0
B16: Marketing / Sale Period (Months) | C16: 0
B17: Total Hold Period (Months) | C17: =C15+C16
C18: Amount | D18: Basis | E18: Total Cost
B19: Loan Interest Carry | C19: 0 | D19: Monthly | E19: =C19*C17
B20: Real Estate Taxes | C20: 0 | D20: Monthly | E20: =C20*C17
B21: Insurance | C21: 0 | D21: Monthly | E21: =C21*C17
B22: Utilities | C22: 0 | D22: Monthly | E22: =C22*C17
B23: Property Maintenance | C23: 0 | D23: Monthly | E23: =C23*C17
B24: HOA / Condo Fees | C24: 0 | D24: Monthly | E24: =C24*C17
B25: Marketing / Advertising | C25: 0 | D25: Total | E25: =C25
B26: Staging / Showing Costs | C26: 0 | D26: Total | E26: =C26
B28: TOTAL CARRY COSTS | E28: =SUM(E19:E26)
B30: ALL-IN BASIS (Project Cost + Carry) | E30: =C12+E28
A32: SALE PROCEEDS
B33: Gross Sale Price (ARV) | C33: 0
B34: Less: Broker Commission (%) | C34: 0.05
B35: Less: Commission Amount | C35: =-C33*C34
B36: Less: Transfer Tax | C36: =-C33*Assumptions!$C$18
B37: Less: Other Closing Costs | C37: 0
B38: Less: Loan Payoff | C38: =-Assumptions!$C$71
B40: NET SALE PROCEEDS | C40: =C33+C35+C36+C37+C38
A42: PROFIT & RETURNS
B43: Net Sale Proceeds | C43: =C40
B44: Less: Total Equity Invested | C44: =-Assumptions!$C$91
B46: NET PROFIT | C46: =C40+C44
B48: Profit Margin (% of Sale) | C48: =IF(C33>0,C46/C33,0)
B49: Return on Equity | C49: =IF(Assumptions!$C$91>0,C46/Assumptions!$C$91,0)
B50: Return on Cost | C50: =IF(E30>0,(C33-E30)/E30,0)
...

Sheet Cash Waterfall
A1: CASH WATERFALL — SALE
A2: Single capital event: money in at close, money out at sale.
A4: PARTNERSHIP STRUCTURE
C5: Amount
B6: GP Equity Contribution (%) | C6: =Assumptions!$C$175
B7: LP Equity Contribution (%) | C7: =Assumptions!$C$176
B8: Total Equity Required | C8: =Assumptions!$C$91
B9: GP Equity ($) | C9: =C6*C8
B10: LP Equity ($) | C10: =C7*C8
A12: MONEY IN — EQUITY INVESTED
C13: Amount
B14: Total Equity Invested | C14: =C8
A16: MONEY OUT — NET SALE PROCEEDS
C17: Amount
B18: Gross Sale Price (ARV) | C18: ='Sale Analysis'!C33
B19: Less: Broker Commission | C19: ='Sale Analysis'!C35
B20: Less: Transfer Tax | C20: ='Sale Analysis'!C36
B21: Less: Other Closing Costs | C21: ='Sale Analysis'!C37
B22: Less: Loan Payoff | C22: ='Sale Analysis'!C38
B24: NET SALE PROCEEDS | C24: ='Sale Analysis'!C40
A26: PROJECT TIMELINE
C27: Months
B28: Construction / Renovation Period | C28: ='Sale Analysis'!C15
B29: Marketing / Sale Period | C29: ='Sale Analysis'!C16
B30: Total Hold Period (Months) | C30: ='Sale Analysis'!C17
B31: Hold Period (Years) | C31: =C30/12
A33: PROJECT-LEVEL RETURNS
C34: Value
B35: Net Profit | C35: =C24-C14
B36: Equity Multiple | C36: =IF(C14>0,C24/C14,0)
B37: Total Return on Equity | C37: =IF(C14>0,C35/C14,0)
B38: Annualized ROE | C38: =IF(AND(C14>0,C31>0),(1+C37)^(1/C31)-1,0)
B39: Project IRR (Annualized) | C39: =IF(AND(C14>0,C30>0,C24>0),IFERROR((1+RATE(C30,0,-C14,C24))^12-1,"N/A"),"N/A")
A41: LP / GP DISTRIBUTION
C42: Amount
B43: LP Share of Proceeds | C43: =IF(C24>0,C10+MAX(0,C35)*Assumptions!$C$178,MAX(C24*C7,0))
B44: GP Share of Proceeds | C44: =C24-C43
B46: LP RETURNS
B47: LP Equity Invested | C47: =C10
B48: LP Total Distributions | C48: =C43
...

Sheet Returns Summary
A1: RETURNS SUMMARY
A2: All values reference other tabs. No hardcoded numbers.
A4: Investment Overview
A5: Property | B5: =Assumptions!C5
A6: Purchase Price | B6: =Assumptions!C17
A7: Total Project Cost | B7: =Assumptions!C89
A8: Total Equity | B8: =Assumptions!C91
A9: Hold Period | B9: =Assumptions!C14
A11: Return Metrics
A12: Year 1 NOI | B12: 0
A13: Going-In Cap Rate | B13: =IF(Assumptions!C17>0,B12/Assumptions!C17,0)
A14: Year 1 Cash-on-Cash | B14: 0
A15: Year 1 DSCR | B15: 0
A16: Exit Cap Rate | B16: =Assumptions!C171
A17: Gross Sale Price | B17: ='Sale Analysis'!C33
A19: Equity Multiple & Distributions
A20: Total Operating CF | B20: 0
A21: Total Refi Proceeds | B21: 0
A22: Net Exit Proceeds | B22: ='Cash Waterfall'!C24
A23: Total Distributions | B23: =B20+B21+B22
A25: EQUITY MULTIPLE | B25: ='Cash Waterfall'!C36
A27: LP IRR (from Waterfall) | B27: 0
A28: LP Equity Multiple | B28: 0
A29: GP IRR | B29: 0
A30: GP Equity Multiple | B30: 0
A31: Levered IRR (Property) | B31: ='Cash Waterfall'!C39

Sheet Sensitivity
A1: SENSITIVITY ANALYSIS
A2: How key returns change across different scenarios. Rent Growth (columns) × Exit Cap Rate (rows).
B4: LEVERED IRR | K4: EQUITY MULTIPLE
B5: Project-level IRR under different rent growth and exit cap assumptions | K5: Project-level equity multiple under different scenarios
B6: Exit Cap ↓ Rent Growth → | C6: =Assumptions!$C$200+0*Assumptions!$C$202 | D6: =Assumptions!$C$200+1*Assumptions!$C$202 | E6: =Assumptions!$C$200+2*Assumptions!$C$202 | F6: =Assumptions!$C$200+3*Assumptions!$C$202 | G6: =Assumptions!$C$200+4*Assumptions!$C$202 | H6: =Assumptions!$C$200+5*Assumptions!$C$202 | K6: Exit Cap ↓ Rent Growth → | L6: =Assumptions!$C$200+0*Assumptions!$C$202 | M6: =Assumptions!$C$200+1*Assumptions!$C$202 | N6: =Assumptions!$C$200+2*Assumptions!$C$202 | O6: =Assumptions!$C$200+3*Assumptions!$C$202 | P6: =Assumptions!$C$200+4*Assumptions!$C$202 | Q6: =Assumptions!$C$200+5*Assumptions!$C$202
B7: =Assumptions!$C$203+0*Assumptions!$C$205 | C7: — | D7: — | E7: — | F7: — | G7: — | H7: — | K7: =Assumptions!$C$203+0*Assumptions!$C$205 | L7: — | M7: — | N7: — | O7: — | P7: — | Q7: —
B8: =Assumptions!$C$203+1*Assumptions!$C$205 | C8: — | D8: — | E8: — | F8: — | G8: — | H8: — | K8: =Assumptions!$C$203+1*Assumptions!$C$205 | L8: — | M8: — | N8: — | O8: — | P8: — | Q8: —
B9: =Assumptions!$C$203+2*Assumptions!$C$205 | C9: — | D9: — | E9: — | F9: — | G9: — | H9: — | K9: =Assumptions!$C$203+2*Assumptions!$C$205 | L9: — | M9: — | N9: — | O9: — | P9: — | Q9: —
B10: =Assumptions!$C$203+3*Assumptions!$C$205 | C10: — | D10: — | E10: — | F10: — | G10: — | H10: — | K10: =Assumptions!$C$203+3*Assumptions!$C$205 | L10: — | M10: — | N10: — | O10: — | P10: — | Q10: —
B11: =Assumptions!$C$203+4*Assumptions!$C$205 | C11: — | D11: — | E11: — | F11: — | G11: — | H11: — | K11: =Assumptions!$C$203+4*Assumptions!$C$205 | L11: — | M11: — | N11: — | O11: — | P11: — | Q11: —
B12: =Assumptions!$C$203+5*Assumptions!$C$205 | C12: — | D12: — | E12: — | F12: — | G12: — | H12: — | K12: =Assumptions!$C$203+5*Assumptions!$C$205 | L12: — | M12: — | N12: — | O12: — | P12: — | Q12: —
B13: =Assumptions!$C$203+6*Assumptions!$C$205 | C13: — | D13: — | E13: — | F13: — | G13: — | H13: — | K13: =Assumptions!$C$203+6*Assumptions!$C$205 | L13: — | M13: — | N13: — | O13: — | P13: — | Q13: —
B15: Values calculated by Python underwriting script (requires iterative IRR calculation). | K15: Values calculated by Python underwriting script.
A16: OPERATING METRICS SENSITIVITY
B18: YEAR 1 NOI | K18: YEAR 1 CASH-ON-CASH RETURN
B19: Vacancy Rate (columns) × Expense Growth (rows) | K19: Purchase Price (columns) × LTV (rows)
B20: Exp Growth ↓ Vacancy → | C20: 0.05 | D20: 0.075 | E20: 0.1 | F20: 0.125 | G20: 0.15 | H20: 0.2 | K20: LTV ↓ Price → | L20: =Assumptions!$C$17*(1+-0.15) | M20: =Assumptions!$C$17*(1+-0.1) | N20: =Assumptions!$C$17*(1+-0.05) | O20: =Assumptions!$C$17 | P20: =Assumptions!$C$17*(1+0.05) | Q20: =Assumptions!$C$17*(1+0.1)
B21: 0.01 | C21: — | D21: — | E21: — | F21: — | G21: — | H21: — | K21: 0.6 | L21: — | M21: — | N21: — | O21: — | P21: — | Q21: —
B22: 0.02 | C22: — | D22: — | E22: — | F22: — | G22: — | H22: — | K22: 0.65 | L22: — | M22: — | N22: — | O22: — | P22: — | Q22: —
B23: 0.03 | C23: — | D23: — | E23: — | F23: — | G23: — | H23: — | K23: 0.7 | L23: — | M23: — | N23: — | O23: — | P23: — | Q23: —
B24: 0.04 | C24: — | D24: — | E24: — | F24: — | G24: — | H24: — | K24: 0.75 | L24: — | M24: — | N24: — | O24: — | P24: — | Q24: —
B25: 0.05 | C25: — | D25: — | E25: — | F25: — | G25: — | H25: — | K25: 0.8 | L25: — | M25: — | N25: — | O25: — | P25: — | Q25: —
B26: Values calculated by Python underwriting script. | K26: Values calculated by Python underwriting script.
